#include <iostream>
using namespace std;

int main() 
{
    try 
    {
        int divisor = 0;
        int result = 10 / divisor;  
    } 
    catch (const std::exception& e) 
    {
        cout << "ExcepciÃ³n capturada: " << e.what() << endl;
    }
    return 0;
}
